Workbook
Name TitleCounties..BA70: Counties!$A$2
Name TitleDatacounties..BZ70: Data!$A$50
Name TitleFTE..K2000: 'PART II-PROGRAM STAFFING'!$A$6
Name TitleReport..E300: '7-OB Report'!$A$9

Sheet 7-OB Report
A1: Title VII-Ch. 2 7-OB Report | C1: Enter Key in cell C2 below
C2: Soc!25$
A3: Organization: | B3: Grant #:
A4: =_xlfn.XLOOKUP($C$2,Data!$C$51:$C$65,Data!$A$51:$A$65) -> Society for the Blind | B4: =_xlfn.XLOOKUP($C$2,Data!$C$51:$C$65,Data!$B$51:$B$65) -> 32539
A5: Quarter: | B5: Grant Year:
B6: 2025/26
A7: Applicable Date Range:
A8: =CONCATENATE("October 1 through ",IF(A6="1st Quarter","December 31",IF(A6="2nd Quarter","March 31",IF(A6="3rd Quarter","June 30",IF(A6="4th Quarter","September 30","unknown"))))) -> October 1 through unknown
A10: Part I
A12: A. Funding Sources and Amounts in Support of the OIB Program for the Reported Federal Fiscal Year (FFY)
A13: 1. Title VII-Chapter 2 Federal grant award for reported FFY – Enter the total amount of your Title VII-Chapter 2 grant award for the reported FFY. Amount must agree with 10d of the Federal Financial Report form (SF-425). | B13: =_xlfn.XLOOKUP($C$2,Data!$C$51:$C$65,Data!$D$51:$D$65) -> 256836
A14: 2. Title VII-Chapter 2 carryover from previous FFY – Enter the amount of Title VII-Chapter 2 grant funds carried over from the previous FFY. Enter zero, if none.
A15: 3. TOTAL Title VII-Chapter 2 funds – The sum of A1 + A2. Total will be automatically populated. | B15: =B13+B14 -> 256836
A16: 4. Title VII-Chapter 1, Part B funds – Enter the total amount of Federal Title VII-Chapter 1, Part B (State Independent Living Services) funds made available for support of the OIB program in the reported FFY.
A17: 5. Other Federal funds available for expenditure in the reported FFY - Enter the total amount of any other Federal funds available for expenditure to support the OIB program for the reported FFY. Other Federal funds may include, but are not limited to, such funds as SSA reimbursement, Title XX Social Security Act funds, and Older Americans Act funds, including the carryover of such funds that are available for expenditure in the reported FFY. | B17: =_xlfn.XLOOKUP($C$2,Data!$C$51:$C$65,Data!$E$51:$E$65) -> 255693
A18: 6. Total Federal funds - Sum of A3 + A4 + A5. Total will be automatically populated. | B18: =SUM(B15:B17) -> 512529
A19: 7. State funds (excluding in-kind contributions) - Enter the total amount of State funds available for expenditure in the OIB program. Include funds from State appropriations as well as funds from other State sources that were available to support the OIB program for the reported FFY.
A20: 8. In-kind contributions - Enter the total dollar amount of fairly evaluated and documented in-kind contributions from state, local, and public agencies, as well as non-profit and for-profit organizations. These can include but are not limited to services, materials, equipment, buildings, or office space that was utilized in support of the OIB program.
A21: 9. Other non-Federal funds - Enter the total amount of funds from other non-Federal sources including local and community funding, non-profit or for-profit agency funding, voluntary client contributions, etc. Do not include in-kind contributions. State funds should be reported in A7 above.
A22: 10. Total non-Federal funds - Sum of A7 + A9 above; do not include In-kind contributions reported in A8. Total will be automatically populated. | B22: =B19+B21 -> 0
A23: 11. Total of all funds available for expenditure in the reported FFY - Sum of A6 + A7 + A9. Do not include in-kind contributions reported in A8. Total will be automatically populated. | B23: =B18+B22 -> 512529
A25: B. OIB Program Expenditures in Reported FFY
A26: 1. Funds expended for administrative costs in the reported FFY - Enter the total amount of funds expended for administrative costs, including administrative support staff and general overhead costs, during the reported FFY. Do not include expenditures for direct services provided by agency staff or the expenditures of contract or sub-grantee staff that provide direct services under contracts or sub-grants. For example, if an administrator spends a portion of his or her time providing administrative services and the remainder providing direct services, include only the expenditures for administrative services.
A27: a. Administrative expenditures from (1) Title VII-Chapter 2 Federal grant award funds, including allowable carryover funds from the previous FFY and (2) non-Federal sources used in meeting the match requirement as reported on line 10j of the SF-425. | C27: =B27/(B27+B31) -> #DIV/0!
A28: b. Administrative expenditures from all other allowable sources as identified in Part I - A above.
A29: c. Total administrative expenditures - Sum of 1a + 1b. Total will be automatically populated. | B29: =B27+B28 -> 0
A30: 2. Funds expended for direct services during the reported FFY - Enter the total funds expended for direct program services during the reported FFY. Amount reported must equal the total funds expended for services in Part IV – F.
A31: a. Direct service expenditures from (1) Title VII-Chapter 2 OIB Federal grant award, including allowable carryover funds from the previous FFY and (2) non-Federal sources used in meeting the match requirement as reported on line 10j of the SF-425.
A32: b. Direct service expenditures from all other allowable sources as identified in Part I - A above.
A33: c. Total direct services expenditures - Sum of 2a + 2b. Total will be automatically populated. | B33: =B31+B32 -> 0
A34: 3. Total funds expended for the program during the reported FFY - Sum of B1c + B2c. Total will be automatically populated. | B34: =B29+B33 -> 0
A36: Part II
A38: A. Full-time Equivalent (FTE) Program Staff Record the FTE administrative and support staff and direct service staff, including State agency staff and contract/subgrant staff, for the OIB program. If a staff member provides both administrative and support functions and direct services, report the percentage of FTE devoted to administrative and support activities under “Administrative & Support” and the percentage of FTE devoted to direct services under “Direct Services.” For example, assuming a full-time 40 hour work week, if 20% (8 hours per week) of a staff person’s time was spent on administrative and support functions related to this program, and 80% (32 hours per week) of the staff person’s time was spent in providing direct services for this program, the reported FTE for that staff person would be 0.2 for administrative and support functions and 0.8 for direct services.
A39: 1. FTE State Agency staff assigned to the OIB program
A40: a. Administrative and support – Under “Administrative & Support,” enter the FTE of all administrative and support staff (e.g., management, program directors, supervisors, readers, drivers for staff, etc.) assigned to the OIB program from the State agency. | B40: ='PART II-PROGRAM STAFFING'!C4 -> 0
A41: b. Direct service – Under “Direct Service”, enter the FTE of all State agency direct service staff (e.g., rehabilitation teachers, Independent Living (IL) specialists, orientation and mobility specialists, social workers, drivers for individuals receiving services, etc.) assigned to the OIB program from the State agency. | B41: ='PART II-PROGRAM STAFFING'!D4 -> 0
A42: c. Total – The total State agency FTE (A1C) is the sum of the “Administrative & Support” FTE (A1A) and “Direct Service” FTE (A1B). Total will be automatically populated. | B42: =B40+B41 -> 0
A43: 2. FTE through contract/subgrant – FTE assigned to the OIB program through a contract or subgrant.
A44: a. Administrative & support – Under “Administrative & Support” (A2a), enter the FTE of all administrative and support staff (e.g., management, program directors, supervisors, readers, drivers for staff, etc.) assigned to the OIB program through contract/subgrant. | B44: ='PART II-PROGRAM STAFFING'!F4 -> 1.21
A45: b. Direct service – Under “Direct Service” (A2b), enter the FTE of all direct service staff (e.g., rehabilitation teachers, independent living specialists, orientation and mobility specialists, social workers, drivers for individuals receiving services, etc.) assigned to the OIB program through contract/subgrant. | B45: ='PART II-PROGRAM STAFFING'!G4 -> 8.04
...

Sheet Instructions
A2: Instructions for 7- OB Report:
A3: 1 | B3: Part II hours for each employee is the weekly average number of hours worked for OIB. To calculate, add up the total number of hours worked in the period covered, then divide by the number of weeks for the applicable period. 1st qtr=13 weeks, 2nd qtr=26 weeks, 3rd quarter=39 weeks, and 4th qtr=52 weeks.
A4: 2 | B4: Please enter in the cell below, the number of hours that constitutes a full-time equivalent (FTE). For example, if full-time is considered 40/hours a week you should enter 40 below. 40 will be used to calculate the FTE values on the Part II program Staffing sheet.
A5: 3 | B5: 40
A6: 2 | B6: Enter participant's names or other identifier on PART III, Column A, Row 17. This list will automatically populate on PART IV-V sheet of services and outcomes.
A7: 3 | B7: All information entered on Parts II, III, IV, and V will be totaled and populate on the 7-OB report tab.
A8: 4 | B8: All items on all sheets must be completed, except for the items that are totaled or calculated automatically.
A9: 5 | B9: You must complete the 'Case Status' column on the Services and Outcomes sheet in order to see options for the three outcome columns that follow as they are dependent on your choice in the case status column.
A10: 6 | B10: If a consumer is 'Assessed' in the 'Case Status' column you must select outcomes for all of the following outcomes. You cannot assess only one outcome.
A11: 7 | B11: Place the key that was provided to you by email in cell C2 on the 7-OB Report sheet. That will auto-populate the organization name, grant number, dollar figures for Part I-A.1&5, as well as targets for the Counties you serve.

Sheet PART II-PROGRAM STAFFING
A1: FTE Part II-FTE | C1: A. Full-time Equivalent (FTE) Program Staff | I1: B. Employees with Disabilities
A2: Data entry begins on Row 7 | C2: State | F2: Contractor | I2: =CONCATENATE(Data!$AO2,": ",Data!$AP2) -> Disabled, not blind or vision impaired: 0
C3: FTE State Agency Admin Support | D3: FTE State Agency Direct Service | E3: Total FTE State Agency | F3: FTE through Contract/ Subgrant Admin Support | G3: FTE through Contract/ Subgrant Direct Service | H3: Total FTE through Contract/ Subgrant | I3: =CONCATENATE(Data!$AO3,": ",Data!$AP3) -> Blind or vision impaired age 55 or older: 4
A4: Totals | C4: =SUMIF($B$7:$B$1999,"State",$C$7:$C$1999) -> 0 | D4: =SUMIF($B$7:$B$1999,"State",$D$7:$D$1999) -> 0 | E4: =SUM(C4:D4) -> 0 | F4: =SUMIF($B$7:$B$1999,"Contractor",$C$7:$C$1999) -> 1.21 | G4: =SUMIF($B$7:$B$1999,"Contractor",$D$7:$D$1999) -> 8.04 | H4: =SUM(F4:G4) -> 9.25 | I4: =CONCATENATE(Data!$AO4,": ",Data!$AP4) -> Blind or vision impaired 54 or younger: 4
A6: Staff Name | B6: State or Contractor | C6: Admin FTE | D6: Direct FTE | E6: Total FTE | F6: Admin Hours | G6: Direct Service Hours | H6: Total | I6: Disability Status
A7: S.Snyder | B7: =IF(A7<>"","Contractor","") -> Contractor | C7: =F7/Instructions!$B$5 -> 0.225 | D7: =G7/Instructions!$B$5 -> 0.025 | E7: =IF(SUM(C7:D7)>1,"Error",SUM(C7:D7)) -> 0.25 | F7: 9 | G7: 1 | H7: =IF(SUM(F7:G7)>Instructions!$B$5,"Error",SUM(F7:G7)) -> 10 | I7: Blind or vision impaired age 55 or older
A8: K.Shevlin | B8: =IF(A8<>"","Contractor","") -> Contractor | C8: =F8/Instructions!$B$5 -> 0.15 | D8: =G8/Instructions!$B$5 -> 0.6 | E8: =IF(SUM(C8:D8)>1,"Error",SUM(C8:D8)) -> 0.75 | F8: 6 | G8: 24 | H8: =IF(SUM(F8:G8)>Instructions!$B$5,"Error",SUM(F8:G8)) -> 30
A9: P. Yeung | B9: =IF(A9<>"","Contractor","") -> Contractor | C9: =F9/Instructions!$B$5 -> 0.16 | D9: =G9/Instructions!$B$5 -> 0.64 | E9: =IF(SUM(C9:D9)>1,"Error",SUM(C9:D9)) -> 0.8 | F9: 6.4 | G9: 25.6 | H9: =IF(SUM(F9:G9)>Instructions!$B$5,"Error",SUM(F9:G9)) -> 32 | I9: Blind or vision impaired 54 or younger
A10: A. Zuniga | B10: =IF(A10<>"","Contractor","") -> Contractor | C10: =F10/Instructions!$B$5 -> 0 | D10: =G10/Instructions!$B$5 -> 1 | E10: =IF(SUM(C10:D10)>1,"Error",SUM(C10:D10)) -> 1 | F10: 0 | G10: 40 | H10: =IF(SUM(F10:G10)>Instructions!$B$5,"Error",SUM(F10:G10)) -> 40 | I10: Blind or vision impaired 54 or younger
A11: D. Celiz | B11: =IF(A11<>"","Contractor","") -> Contractor | C11: =F11/Instructions!$B$5 -> 0 | D11: =G11/Instructions!$B$5 -> 0.25 | E11: =IF(SUM(C11:D11)>1,"Error",SUM(C11:D11)) -> 0.25 | F11: 0 | G11: 10 | H11: =IF(SUM(F11:G11)>Instructions!$B$5,"Error",SUM(F11:G11)) -> 10 | I11: Blind or vision impaired age 55 or older
A12: D. Pendleton | B12: =IF(A12<>"","Contractor","") -> Contractor | C12: =F12/Instructions!$B$5 -> 0 | D12: =G12/Instructions!$B$5 -> 1 | E12: =IF(SUM(C12:D12)>1,"Error",SUM(C12:D12)) -> 1 | F12: 0 | G12: 40 | H12: =IF(SUM(F12:G12)>Instructions!$B$5,"Error",SUM(F12:G12)) -> 40 | I12: Blind or vision impaired age 55 or older
A13: R. Cummings | B13: =IF(A13<>"","Contractor","") -> Contractor | C13: =F13/Instructions!$B$5 -> 0 | D13: =G13/Instructions!$B$5 -> 1 | E13: =IF(SUM(C13:D13)>1,"Error",SUM(C13:D13)) -> 1 | F13: 0 | G13: 40 | H13: =IF(SUM(F13:G13)>Instructions!$B$5,"Error",SUM(F13:G13)) -> 40 | I13: Blind or vision impaired age 55 or older
A14: G. Hunter | B14: =IF(A14<>"","Contractor","") -> Contractor | C14: =F14/Instructions!$B$5 -> 0.2 | D14: =G14/Instructions!$B$5 -> 0.8 | E14: =IF(SUM(C14:D14)>1,"Error",SUM(C14:D14)) -> 1 | F14: 8 | G14: 32 | H14: =IF(SUM(F14:G14)>Instructions!$B$5,"Error",SUM(F14:G14)) -> 40
A15: L. Williams | B15: =IF(A15<>"","Contractor","") -> Contractor | C15: =F15/Instructions!$B$5 -> 0.2 | D15: =G15/Instructions!$B$5 -> 0.8 | E15: =IF(SUM(C15:D15)>1,"Error",SUM(C15:D15)) -> 1 | F15: 8 | G15: 32 | H15: =IF(SUM(F15:G15)>Instructions!$B$5,"Error",SUM(F15:G15)) -> 40
A16: H. Pham | B16: =IF(A16<>"","Contractor","") -> Contractor | C16: =F16/Instructions!$B$5 -> 0 | D16: =G16/Instructions!$B$5 -> 0.4 | E16: =IF(SUM(C16:D16)>1,"Error",SUM(C16:D16)) -> 0.4 | F16: 0 | G16: 16 | H16: =IF(SUM(F16:G16)>Instructions!$B$5,"Error",SUM(F16:G16)) -> 16 | I16: Blind or vision impaired 54 or younger
A17: T. Peterson | B17: =IF(A17<>"","Contractor","") -> Contractor | C17: =F17/Instructions!$B$5 -> 0.1 | D17: =G17/Instructions!$B$5 -> 0 | E17: =IF(SUM(C17:D17)>1,"Error",SUM(C17:D17)) -> 0.1 | F17: 4 | H17: =IF(SUM(F17:G17)>Instructions!$B$5,"Error",SUM(F17:G17)) -> 4
A18: R. Edwards | B18: =IF(A18<>"","Contractor","") -> Contractor | C18: =F18/Instructions!$B$5 -> 0 | D18: =G18/Instructions!$B$5 -> 0.8 | E18: =IF(SUM(C18:D18)>1,"Error",SUM(C18:D18)) -> 0.8 | G18: 32 | H18: =IF(SUM(F18:G18)>Instructions!$B$5,"Error",SUM(F18:G18)) -> 32 | I18: Blind or vision impaired 54 or younger
A19: O. Walker | B19: =IF(A19<>"","Contractor","") -> Contractor | C19: =F19/Instructions!$B$5 -> 0.175 | D19: =G19/Instructions!$B$5 -> 0.725 | E19: =IF(SUM(C19:D19)>1,"Error",SUM(C19:D19)) -> 0.9 | F19: 7 | G19: 29 | H19: =IF(SUM(F19:G19)>Instructions!$B$5,"Error",SUM(F19:G19)) -> 36
B20: =IF(A20<>"","Contractor","") | C20: =F20/Instructions!$B$5 -> 0 | D20: =G20/Instructions!$B$5 -> 0 | E20: =IF(SUM(C20:D20)>1,"Error",SUM(C20:D20)) -> 0 | H20: =IF(SUM(F20:G20)>Instructions!$B$5,"Error",SUM(F20:G20)) -> 0
B21: =IF(A21<>"","Contractor","") | C21: =F21/Instructions!$B$5 -> 0 | D21: =G21/Instructions!$B$5 -> 0 | E21: =IF(SUM(C21:D21)>1,"Error",SUM(C21:D21)) -> 0 | H21: =IF(SUM(F21:G21)>Instructions!$B$5,"Error",SUM(F21:G21)) -> 0
B22: =IF(A22<>"","Contractor","") | C22: =F22/Instructions!$B$5 -> 0 | D22: =G22/Instructions!$B$5 -> 0 | E22: =IF(SUM(C22:D22)>1,"Error",SUM(C22:D22)) -> 0 | H22: =IF(SUM(F22:G22)>Instructions!$B$5,"Error",SUM(F22:G22)) -> 0
B23: =IF(A23<>"","Contractor","") | C23: =F23/Instructions!$B$5 -> 0 | D23: =G23/Instructions!$B$5 -> 0 | E23: =IF(SUM(C23:D23)>1,"Error",SUM(C23:D23)) -> 0 | H23: =IF(SUM(F23:G23)>Instructions!$B$5,"Error",SUM(F23:G23)) -> 0
B24: =IF(A24<>"","Contractor","") | C24: =F24/Instructions!$B$5 -> 0 | D24: =G24/Instructions!$B$5 -> 0 | E24: =IF(SUM(C24:D24)>1,"Error",SUM(C24:D24)) -> 0 | H24: =IF(SUM(F24:G24)>Instructions!$B$5,"Error",SUM(F24:G24)) -> 0
B25: =IF(A25<>"","Contractor","") | C25: =F25/Instructions!$B$5 -> 0 | D25: =G25/Instructions!$B$5 -> 0 | E25: =IF(SUM(C25:D25)>1,"Error",SUM(C25:D25)) -> 0 | H25: =IF(SUM(F25:G25)>Instructions!$B$5,"Error",SUM(F25:G25)) -> 0
B26: =IF(A26<>"","Contractor","") | C26: =F26/Instructions!$B$5 -> 0 | D26: =G26/Instructions!$B$5 -> 0 | E26: =IF(SUM(C26:D26)>1,"Error",SUM(C26:D26)) -> 0 | H26: =IF(SUM(F26:G26)>Instructions!$B$5,"Error",SUM(F26:G26)) -> 0
B27: =IF(A27<>"","Contractor","") | C27: =F27/Instructions!$B$5 -> 0 | D27: =G27/Instructions!$B$5 -> 0 | E27: =IF(SUM(C27:D27)>1,"Error",SUM(C27:D27)) -> 0 | H27: =IF(SUM(F27:G27)>Instructions!$B$5,"Error",SUM(F27:G27)) -> 0
B28: =IF(A28<>"","Contractor","") | C28: =F28/Instructions!$B$5 -> 0 | D28: =G28/Instructions!$B$5 -> 0 | E28: =IF(SUM(C28:D28)>1,"Error",SUM(C28:D28)) -> 0 | H28: =IF(SUM(F28:G28)>Instructions!$B$5,"Error",SUM(F28:G28)) -> 0
B29: =IF(A29<>"","Contractor","") | C29: =F29/Instructions!$B$5 -> 0 | D29: =G29/Instructions!$B$5 -> 0 | E29: =IF(SUM(C29:D29)>1,"Error",SUM(C29:D29)) -> 0 | H29: =IF(SUM(F29:G29)>Instructions!$B$5,"Error",SUM(F29:G29)) -> 0
B30: =IF(A30<>"","Contractor","") | C30: =F30/Instructions!$B$5 -> 0 | D30: =G30/Instructions!$B$5 -> 0 | E30: =IF(SUM(C30:D30)>1,"Error",SUM(C30:D30)) -> 0 | H30: =IF(SUM(F30:G30)>Instructions!$B$5,"Error",SUM(F30:G30)) -> 0
B31: =IF(A31<>"","Contractor","") | C31: =F31/Instructions!$B$5 -> 0 | D31: =G31/Instructions!$B$5 -> 0 | E31: =IF(SUM(C31:D31)>1,"Error",SUM(C31:D31)) -> 0 | H31: =IF(SUM(F31:G31)>Instructions!$B$5,"Error",SUM(F31:G31)) -> 0
... B51: =IF(A51<>"","Contractor","") | C51: =F51/Instructions!$B$5 -> 0 | D51: =G51/Instructions!$B$5 -> 0 | E51: =IF(SUM(C51:D51)>1,"Error",SUM(C51:D51)) -> 0 | H51: =IF(SUM(F51:G51)>Instructions!$B$5,"Error",SUM(F51:G51)) -> 0
C52: =F52/Instructions!$B$5 -> 0 | D52: =G52/Instructions!$B$5 -> 0 | E52: =IF(SUM(C52:D52)>1,"Error",SUM(C52:D52)) -> 0 | H52: =IF(SUM(F52:G52)>Instructions!$B$5,"Error",SUM(F52:G52)) -> 0
C53: =F53/Instructions!$B$5 -> 0 | D53: =G53/Instructions!$B$5 -> 0 | E53: =IF(SUM(C53:D53)>1,"Error",SUM(C53:D53)) -> 0 | H53: =IF(SUM(F53:G53)>Instructions!$B$5,"Error",SUM(F53:G53)) -> 0
C54: =F54/Instructions!$B$5 -> 0 | D54: =G54/Instructions!$B$5 -> 0 | E54: =IF(SUM(C54:D54)>1,"Error",SUM(C54:D54)) -> 0 | H54: =IF(SUM(F54:G54)>Instructions!$B$5,"Error",SUM(F54:G54)) -> 0
C55: =F55/Instructions!$B$5 -> 0 | D55: =G55/Instructions!$B$5 -> 0 | E55: =IF(SUM(C55:D55)>1,"Error",SUM(C55:D55)) -> 0 | H55: =IF(SUM(F55:G55)>Instructions!$B$5,"Error",SUM(F55:G55)) -> 0
C56: =F56/Instructions!$B$5 -> 0 | D56: =G56/Instructions!$B$5 -> 0 | E56: =IF(SUM(C56:D56)>1,"Error",SUM(C56:D56)) -> 0 | H56: =IF(SUM(F56:G56)>Instructions!$B$5,"Error",SUM(F56:G56)) -> 0
C57: =F57/Instructions!$B$5 -> 0 | D57: =G57/Instructions!$B$5 -> 0 | E57: =IF(SUM(C57:D57)>1,"Error",SUM(C57:D57)) -> 0 | H57: =IF(SUM(F57:G57)>Instructions!$B$5,"Error",SUM(F57:G57)) -> 0
C58: =F58/Instructions!$B$5 -> 0 | D58: =G58/Instructions!$B$5 -> 0 | E58: =IF(SUM(C58:D58)>1,"Error",SUM(C58:D58)) -> 0 | H58: =IF(SUM(F58:G58)>Instructions!$B$5,"Error",SUM(F58:G58)) -> 0
C59: =F59/Instructions!$B$5 -> 0 | D59: =G59/Instructions!$B$5 -> 0 | E59: =IF(SUM(C59:D59)>1,"Error",SUM(C59:D59)) -> 0 | H59: =IF(SUM(F59:G59)>Instructions!$B$5,"Error",SUM(F59:G59)) -> 0
C60: =F60/Instructions!$B$5 -> 0 | D60: =G60/Instructions!$B$5 -> 0 | E60: =IF(SUM(C60:D60)>1,"Error",SUM(C60:D60)) -> 0 | H60: =IF(SUM(F60:G60)>Instructions!$B$5,"Error",SUM(F60:G60)) -> 0
...

Sheet PART III-DEMOGRAPHICS
A1: Participant Name | B1: A. Individuals Served | C1: B. Age at Application | D1: C. Gender | E1: D. Race | F1: E. Ethnicity | G1: F. Degree of Visual Impairment | H1: G. Major Cause of Visual Impairment | I1: H. Other Age-Related Impairments | O1: I. Type of Residence | P1: J. Source of Referral | Q1: County of Residence | R1: Possible Duplicate
A2: Row 17 begin data entry. | B2: =CONCATENATE(Data!A2,": ",Data!B2) -> Case open prior to Oct. 1: 0 | C2: =CONCATENATE(Data!C2,": ",Data!D2) -> 55-64: 0 | D2: =CONCATENATE(Data!E2,": ",Data!F2) -> Female: 0 | E2: =CONCATENATE(Data!G2,": ",Data!H2) -> American Indian or Alaska Native: 0 | F2: =CONCATENATE(Data!I2,": ",Data!J2) -> Hispanic or Latino: 0 | G2: =CONCATENATE(Data!K2,": ",Data!L2) -> Totally Blind: 0 | H2: =CONCATENATE(Data!M2,": ",Data!N2) -> Macular Degeneration: 0 | I2: =CONCATENATE(Data!$O2,": ",Data!$P2) -> Hearing Impairment: 0 | J2: =CONCATENATE(Data!$O3,": ",Data!$P3) -> Mobility Impairment: 0 | K2: =CONCATENATE(Data!$O4,": ",Data!$P4) -> Communication Impairment: 0 | L2: =CONCATENATE(Data!$O5,": ",Data!$P5) -> Cognitive or Intellectual Impairment: 0 | M2: =CONCATENATE(Data!$O6,": ",Data!$P6) -> Mental Health Impairment: 0 | N2: =CONCATENATE(Data!$O7,": ",Data!$P7) -> Other Impairment: 0 | O2: =CONCATENATE(Data!$Q2,": ",Data!$R2) -> Private Residence: 0 | P2: =CONCATENATE(Data!$S2,": ",Data!$T2) -> Eye Care Provider: 0 | Q2: See Counties Sheet for detail
B3: =CONCATENATE(Data!A3,": ",Data!B3) -> Case open between Oct. 1 - Sept. 30: 0 | C3: =CONCATENATE(Data!C3,": ",Data!D3) -> 65-74: 0 | D3: =CONCATENATE(Data!E3,": ",Data!F3) -> Male: 0 | E3: =CONCATENATE(Data!G3,": ",Data!H3) -> Asian: 0 | G3: =CONCATENATE(Data!K3,": ",Data!L3) -> Legally Blind: 0 | H3: =CONCATENATE(Data!M3,": ",Data!N3) -> Diabetic Retinopathy: 0 | O3: =CONCATENATE(Data!$Q3,": ",Data!$R3) -> Senior Independent Living: 0 | P3: =CONCATENATE(Data!$S3,": ",Data!$T3) -> Physician/ Medical Provider: 0
B4: =CONCATENATE(Data!A4,": ",Data!B4) -> Total: 0 | C4: =CONCATENATE(Data!C4,": ",Data!D4) -> 75-84: 0 | D4: =CONCATENATE(Data!E4,": ",Data!F4) -> Did Not Self-Identify: 0 | E4: =CONCATENATE(Data!G4,": ",Data!H4) -> Black or African American: 0 | G4: =CONCATENATE(Data!K4,": ",Data!L4) -> Severe Vision Impairment: 0 | H4: =CONCATENATE(Data!M4,": ",Data!N4) -> Glaucoma: 0 | O4: =CONCATENATE(Data!$Q4,": ",Data!$R4) -> Assisted Living Facility: 0 | P4: =CONCATENATE(Data!$S4,": ",Data!$T4) -> State VR Agency: 0
C5: =CONCATENATE(Data!C5,": ",Data!D5) -> 85 and older: 0 | D5: =CONCATENATE(Data!E5,": ",Data!F5) -> Total: 0 | E5: =CONCATENATE(Data!G5,": ",Data!H5) -> Native Hawaiian or Pacific Islander: 0 | G5: =CONCATENATE(Data!K5,": ",Data!L5) -> Total: 0 | H5: =CONCATENATE(Data!M5,": ",Data!N5) -> Cataracts: 0 | O5: =CONCATENATE(Data!$Q5,": ",Data!$R5) -> Nursing Home: 0 | P5: =CONCATENATE(Data!$S5,": ",Data!$T5) -> Social Service: 0
C6: =CONCATENATE(Data!C6,": ",Data!D6) -> Total: 0 | E6: =CONCATENATE(Data!G6,": ",Data!H6) -> White: 0 | H6: =CONCATENATE(Data!M6,": ",Data!N6) -> Other causes: 0 | O6: =CONCATENATE(Data!$Q6,": ",Data!$R6) -> Homeless: 0 | P6: =CONCATENATE(Data!$S6,": ",Data!$T6) -> Veterans Administration: 0
E7: =CONCATENATE(Data!G7,": ",Data!H7) -> Did not self identify Race: 0 | H7: =CONCATENATE(Data!M7,": ",Data!N7) -> Total: 0 | O7: =CONCATENATE(Data!$Q7,": ",Data!$R7) -> Total: 0 | P7: =CONCATENATE(Data!$S7,": ",Data!$T7) -> Senior Program: 0
E8: =CONCATENATE(Data!G8,": ",Data!H8) -> 2 or More Races: 0 | P8: =CONCATENATE(Data!$S8,": ",Data!$T8) -> Assisted Living Facility: 0
E9: =CONCATENATE(Data!G9,": ",Data!H9) -> Total: 0 | P9: =CONCATENATE(Data!$S9,": ",Data!$T9) -> Nursing Home: 0
P10: =CONCATENATE(Data!$S10,": ",Data!$T10) -> Independent Living Center: 0
P11: =CONCATENATE(Data!$S11,": ",Data!$T11) -> Family or Friend: 0
P12: =CONCATENATE(Data!$S12,": ",Data!$T12) -> Self-Referral: 0
P13: =CONCATENATE(Data!$S13,": ",Data!$T13) -> Other: 0
A14: (Note: If cell A16 shows "TRUE", the demographic data totals match as required on the 7-OB report. "FALSE" indicates a data input error has occurred and needs to be corrected. | P14: =CONCATENATE(Data!$S14,": ",Data!$T14) -> Total: 0
A15: Check cells to the right to verify that the totals in row 16 are accurate. | C15: =IF(C16=$B$16,"Accurate","ERROR!") -> Accurate | D15: =IF(D16=$B$16,"Accurate","ERROR!") -> Accurate | E15: =IF(E16=$B$16,"Accurate","ERROR!") -> Accurate | F15: N/A | G15: =IF(G16=$B$16,"Accurate","ERROR!") -> Accurate | H15: =IF(H16=$B$16,"Accurate","ERROR!") -> Accurate | I15: N/A | J15: N/A | K15: N/A | L15: N/A | M15: N/A | N15: N/A | O15: =IF(O16=$B$16,"Accurate","ERROR!") -> Accurate | P15: =IF(P16=$B$16,"Accurate","ERROR!") -> Accurate | Q15: =IF(Q16=$B$16,"Accurate","ERROR!") -> Accurate | R15: =IF(R16=0,"No Duplicate Names","Possible Duplicate in rows below") -> No Duplicate Names
A16: =AND(EXACT(B16,C16),EXACT(B16,D16),EXACT(B16,E16),EXACT(B16,G16),EXACT(B16,H16),EXACT(B16,O16),EXACT(B16,P16),EXACT(B16,Q16)) -> TRUE | B16: =Data!B4 -> 0 | C16: =Data!D6 -> 0 | D16: =Data!F5 -> 0 | E16: =Data!H9 -> 0 | F16: =Data!J2 -> 0 | G16: =Data!L5 -> 0 | H16: =Data!N7 -> 0 | I16: =Data!$P2 -> 0 | J16: =Data!$P3 -> 0 | K16: =Data!$P4 -> 0 | L16: =Data!$P5 -> 0 | M16: =Data!$P6 -> 0 | N16: =Data!$P7 -> 0 | O16: =Data!$R7 -> 0 | P16: =Data!$T14 -> 0 | Q16: =COUNTA(Q17:Q2010) -> 0 | R16: =IF(COUNTIF(R17:R2010,"Possible Duplicate")>0,COUNTIF(R17:R2010,"Possible Duplicate"),0) -> 0
R17: =IF(COUNTIF($A$17:$A$2010,$A17)>1,"Possible Duplicate","")
R18: =IF(COUNTIF($A$17:$A$2010,$A18)>1,"Possible Duplicate","")
R19: =IF(COUNTIF($A$17:$A$2010,$A19)>1,"Possible Duplicate","")
R20: =IF(COUNTIF($A$17:$A$2010,$A20)>1,"Possible Duplicate","")
R21: =IF(COUNTIF($A$17:$A$2010,$A21)>1,"Possible Duplicate","")
R22: =IF(COUNTIF($A$17:$A$2010,$A22)>1,"Possible Duplicate","")
R23: =IF(COUNTIF($A$17:$A$2010,$A23)>1,"Possible Duplicate","")
R24: =IF(COUNTIF($A$17:$A$2010,$A24)>1,"Possible Duplicate","")
R25: =IF(COUNTIF($A$17:$A$2010,$A25)>1,"Possible Duplicate","")
R26: =IF(COUNTIF($A$17:$A$2010,$A26)>1,"Possible Duplicate","")
R27: =IF(COUNTIF($A$17:$A$2010,$A27)>1,"Possible Duplicate","")
R28: =IF(COUNTIF($A$17:$A$2010,$A28)>1,"Possible Duplicate","")
... R2010: =IF(COUNTIF($A$17:$A$2010,$A2010)>1,"Possible Duplicate","")

Sheet PART IV-V-SERVICES AND OUTCOMES
A1: Participant Name | B1: A. Clinical/functional Vision Assessments and Services | D1: B. Assistive Technology Devices and Services | E1: AT Goal Outcomes | F1: C. Independent Living and Adjustment Services | N1: IL/A Service Goal Outcomes | O1: D. Supportive Services | P1: Case Status | Q1: Living Situation Outcomes | R1: Home and Community involvement Outcomes | S1: Employment Outcome | T1: Number of Services | U1: County (populates from Demographics tab) | AG1: Status | AH1: Assessed | AI1: Pending
A2: row 7 begin data entry. | B2: =CONCATENATE(Data!$U$2,": ",Data!$V$2) -> Vision Assessment (Screening/ Exam/evaluation: 0 | C2: =CONCATENATE(Data!$U$3,": ",Data!$V$3) -> Surgical or Therapeutic Treatment: 0 | D2: =CONCATENATE(Data!$W$2,": ",Data!$X$2) -> Received AT Devices or Services: 0 | E2: =CONCATENATE(Data!$Y$2,": ",Data!$Z$2) -> Not Assessed: 0 | F2: =CONCATENATE(Data!$AA$2,": ",Data!$AB$2) -> Received IL/A Services: 0 | G2: =CONCATENATE(Data!$AA$3,": ",Data!$AB$3) -> Received O&M: 0 | H2: =CONCATENATE(Data!$AA$4,": ",Data!$AB$4) -> Received Communication Skills: 0 | I2: =CONCATENATE(Data!$AA$5,": ",Data!$AB$5) -> Received Daily Living Skills: 0 | J2: =CONCATENATE(Data!$AA$6,": ",Data!$AB$6) -> Received Advocacy Training: 0 | K2: =CONCATENATE(Data!$AA$7,": ",Data!$AB$7) -> Received Adjustment Counseling: 0 | L2: =CONCATENATE(Data!$AA$8,": ",Data!$AB$8) -> Received I&R: 0 | M2: =CONCATENATE(Data!$AA$9,": ",Data!$AB$9) -> Received Other Services: 0 | N2: =CONCATENATE(Data!$AC2,": ",Data!$AD2) -> Not Assessed: 0 | O2: =CONCATENATE(Data!$AE$2,": ",Data!$AF$2) -> Received Supportive Service: 0 | P2: =CONCATENATE(Data!$AG$2,": ",Data!$AH$2) -> # of Cases Assessed: 0 | Q2: =CONCATENATE(Data!$AI2,": ",Data!$AJ2) -> Plan Incomplete-Not Assessed: 0 | R2: =CONCATENATE(Data!$AK2,": ",Data!$AL2) -> Plan Incomplete-Not Assessed: 0 | S2: =CONCATENATE(Data!$AM2,": ",Data!$AN2) -> Plan Incomplete-Not Assessed: 0 | T2: Total number of services provided to consumers
E3: =CONCATENATE(Data!$Y$3,": ",Data!$Z$3) -> Assessed with Increased Independence: 0 | N3: =CONCATENATE(Data!$AC3,": ",Data!$AD3) -> Assessed with Increased Independence: 0 | Q3: =CONCATENATE(Data!$AI3,": ",Data!$AJ3) -> Plan Completed - Reported feeling more confident in ability to maintain living situation: 0 | R3: =CONCATENATE(Data!$AK3,": ",Data!$AL3) -> Plan Completed - Reported an increased ability to engage in customary activities : 0 | S3: =CONCATENATE(Data!$AM3,": ",Data!$AN3) -> Not Interested in Employment: 0
E4: =CONCATENATE(Data!$Y$4,": ",Data!$Z$4) -> Assessed and Maintained Independence: 0 | N4: =CONCATENATE(Data!$AC4,": ",Data!$AD4) -> Assessed and Maintained Independence: 0 | Q4: =CONCATENATE(Data!$AI4,": ",Data!$AJ4) -> Plan Completed - Reported no difference in ability to maintain living situation: 0 | R4: =CONCATENATE(Data!$AK4,": ",Data!$AL4) -> Plan Completed - Reported no difference in ability to engage in customary activities : 0 | S4: =CONCATENATE(Data!$AM4,": ",Data!$AN4) -> Less Likely to Seek Employment: 0
E5: =CONCATENATE(Data!$Y$5,": ",Data!$Z$5) -> Assessed with Decreased Independence: 0 | N5: =CONCATENATE(Data!$AC5,": ",Data!$AD5) -> Assessed with Decreased Independence: 0 | Q5: =CONCATENATE(Data!$AI5,": ",Data!$AJ5) -> Plan Completed - Reported feeling less confident in ability to maintain living situation: 0 | R5: =CONCATENATE(Data!$AK5,": ",Data!$AL5) -> Plan Completed - Reported a decreased ability to engage in customary activities: 0 | S5: =CONCATENATE(Data!$AM5,": ",Data!$AN5) -> Unsure about Seeking Employment: 0
S6: =CONCATENATE(Data!$AM6,": ",Data!$AN6) -> More Likely to Seek Employment: 0
A7: =IF('PART III-DEMOGRAPHICS'!A17="","",'PART III-DEMOGRAPHICS'!A17) | F7: =IF(OR(G7="Yes",H7="Yes",I7="Yes",J7="Yes",K7="Yes",L7="Yes",M7="Yes"),"Did","Did Not") -> Did Not | T7: =COUNTIF(A7:R7,"Yes") -> 0 | U7: =IF('PART III-DEMOGRAPHICS'!Q17="","",'PART III-DEMOGRAPHICS'!Q17)
A8: =IF('PART III-DEMOGRAPHICS'!A18="","",'PART III-DEMOGRAPHICS'!A18) | F8: =IF(OR(G8="Yes",H8="Yes",I8="Yes",J8="Yes",K8="Yes",L8="Yes",M8="Yes"),"Did","Did Not") -> Did Not | T8: =COUNTIF(A8:R8,"Yes") -> 0 | U8: =IF('PART III-DEMOGRAPHICS'!Q18="","",'PART III-DEMOGRAPHICS'!Q18)
A9: =IF('PART III-DEMOGRAPHICS'!A19="","",'PART III-DEMOGRAPHICS'!A19) | F9: =IF(OR(G9="Yes",H9="Yes",I9="Yes",J9="Yes",K9="Yes",L9="Yes",M9="Yes"),"Did","Did Not") -> Did Not | T9: =COUNTIF(A9:R9,"Yes") -> 0 | U9: =IF('PART III-DEMOGRAPHICS'!Q19="","",'PART III-DEMOGRAPHICS'!Q19)
A10: =IF('PART III-DEMOGRAPHICS'!A20="","",'PART III-DEMOGRAPHICS'!A20) | F10: =IF(OR(G10="Yes",H10="Yes",I10="Yes",J10="Yes",K10="Yes",L10="Yes",M10="Yes"),"Did","Did Not") -> Did Not | T10: =COUNTIF(A10:R10,"Yes") -> 0 | U10: =IF('PART III-DEMOGRAPHICS'!Q20="","",'PART III-DEMOGRAPHICS'!Q20)
A11: =IF('PART III-DEMOGRAPHICS'!A21="","",'PART III-DEMOGRAPHICS'!A21) | F11: =IF(OR(G11="Yes",H11="Yes",I11="Yes",J11="Yes",K11="Yes",L11="Yes",M11="Yes"),"Did","Did Not") -> Did Not | T11: =COUNTIF(A11:R11,"Yes") -> 0 | U11: =IF('PART III-DEMOGRAPHICS'!Q21="","",'PART III-DEMOGRAPHICS'!Q21)
A12: =IF('PART III-DEMOGRAPHICS'!A22="","",'PART III-DEMOGRAPHICS'!A22) | F12: =IF(OR(G12="Yes",H12="Yes",I12="Yes",J12="Yes",K12="Yes",L12="Yes",M12="Yes"),"Did","Did Not") -> Did Not | T12: =COUNTIF(A12:R12,"Yes") -> 0 | U12: =IF('PART III-DEMOGRAPHICS'!Q22="","",'PART III-DEMOGRAPHICS'!Q22)
A13: =IF('PART III-DEMOGRAPHICS'!A23="","",'PART III-DEMOGRAPHICS'!A23) | F13: =IF(OR(G13="Yes",H13="Yes",I13="Yes",J13="Yes",K13="Yes",L13="Yes",M13="Yes"),"Did","Did Not") -> Did Not | T13: =COUNTIF(A13:R13,"Yes") -> 0 | U13: =IF('PART III-DEMOGRAPHICS'!Q23="","",'PART III-DEMOGRAPHICS'!Q23)
A14: =IF('PART III-DEMOGRAPHICS'!A24="","",'PART III-DEMOGRAPHICS'!A24) | F14: =IF(OR(G14="Yes",H14="Yes",I14="Yes",J14="Yes",K14="Yes",L14="Yes",M14="Yes"),"Did","Did Not") -> Did Not | T14: =COUNTIF(A14:R14,"Yes") -> 0 | U14: =IF('PART III-DEMOGRAPHICS'!Q24="","",'PART III-DEMOGRAPHICS'!Q24)
A15: =IF('PART III-DEMOGRAPHICS'!A25="","",'PART III-DEMOGRAPHICS'!A25) | F15: =IF(OR(G15="Yes",H15="Yes",I15="Yes",J15="Yes",K15="Yes",L15="Yes",M15="Yes"),"Did","Did Not") -> Did Not | T15: =COUNTIF(A15:R15,"Yes") -> 0 | U15: =IF('PART III-DEMOGRAPHICS'!Q25="","",'PART III-DEMOGRAPHICS'!Q25)
A16: =IF('PART III-DEMOGRAPHICS'!A26="","",'PART III-DEMOGRAPHICS'!A26) | F16: =IF(OR(G16="Yes",H16="Yes",I16="Yes",J16="Yes",K16="Yes",L16="Yes",M16="Yes"),"Did","Did Not") -> Did Not | T16: =COUNTIF(A16:R16,"Yes") -> 0 | U16: =IF('PART III-DEMOGRAPHICS'!Q26="","",'PART III-DEMOGRAPHICS'!Q26)
A17: =IF('PART III-DEMOGRAPHICS'!A27="","",'PART III-DEMOGRAPHICS'!A27) | F17: =IF(OR(G17="Yes",H17="Yes",I17="Yes",J17="Yes",K17="Yes",L17="Yes",M17="Yes"),"Did","Did Not") -> Did Not | T17: =COUNTIF(A17:R17,"Yes") -> 0 | U17: =IF('PART III-DEMOGRAPHICS'!Q27="","",'PART III-DEMOGRAPHICS'!Q27)
A18: =IF('PART III-DEMOGRAPHICS'!A28="","",'PART III-DEMOGRAPHICS'!A28) | F18: =IF(OR(G18="Yes",H18="Yes",I18="Yes",J18="Yes",K18="Yes",L18="Yes",M18="Yes"),"Did","Did Not") -> Did Not | T18: =COUNTIF(A18:R18,"Yes") -> 0 | U18: =IF('PART III-DEMOGRAPHICS'!Q28="","",'PART III-DEMOGRAPHICS'!Q28)
... A2000: =IF('PART III-DEMOGRAPHICS'!A2010="","",'PART III-DEMOGRAPHICS'!A2010) | F2000: =IF(OR(G2000="Yes",H2000="Yes",I2000="Yes",J2000="Yes",K2000="Yes",L2000="Yes",M2000="Yes"),"Did","Did Not") -> Did Not | T2000: =COUNTIF(A2000:R2000,"Yes") -> 0 | U2000: =IF('PART III-DEMOGRAPHICS'!Q2010="","",'PART III-DEMOGRAPHICS'!Q2010)

Sheet Counties
A1: 2526
A2: County | B2: Count | C2: Target | D2: Percentage | F2: Count American Indian/ Alaska Native | G2: % American Indian/ Alaska Native | H2: Target % American Indian/ Alaska Native | I2: Met Target | J2: Count Asian | K2: % Asian | L2: Target % Asian | M2: Met Target | N2: Count Black/ African American | O2: % Black/ African American | P2: Target % Black/ African American | Q2: Met Target | R2: Count Native Hawaiian/ Pacific Islander | S2: % Native Hawaiian/ Pacific Islander | T2: Target % Native Hawaiian/ Pacific Islander | U2: Met Target | V2: Count Hispanic/ LatinX | W2: % Hispanic/ LatinX | X2: Target % Hispanic/LatinX | Y2: Met Target | Z2: Count White | AA2: % White | AB2: Target % White | AC2: Met Target | AD2: Count Multiracial | AE2: % Multiracial | AF2: Target % Multiracial | AG2: Met Target | AH2: Count Did Not Identify | AI2: % Did Not Identify | AK2: # of Services | AL2: Average Number of Services/ Consumer
A4: Alameda | B4: =COUNTIF('PART III-DEMOGRAPHICS'!$Q$17:$Q$2010,A4) -> 0 | C4: {=IF(_xlfn.XLOOKUP('7-OB Report'!$C$2,Data!$C$51:$C$65,_xlfn.XLOOKUP($A4,Data!$F$50:$BM$50,Data!$F$51:$BM$65))=0,"",_xlfn.XLOOKUP('7-OB Report'!$C$2,Data!$C$51:$C$65,_xlfn.XLOOKUP($A4,Data!$F$50:$BM$50,Data!$F$51:$BM$65)))} | D4: =IF(C4="","",B4/C4) | F4: =IF($B4=0,"",COUNTIFS('PART III-DEMOGRAPHICS'!$E$17:$E$2010,Data!$G$2,'PART III-DEMOGRAPHICS'!$Q$17:$Q$2010,$A4)) | G4: =IF($B4=0,"",$F4/$B4) | H4: 0.0031691601 | I4: =IF($B4=0,"",(IF(G4>=H4,"Met","Unmet"))) | J4: =IF($B4=0,"",COUNTIFS('PART III-DEMOGRAPHICS'!$E$17:$E$2010,Data!$G$3,'PART III-DEMOGRAPHICS'!$Q$17:$Q$2010,$A4)) | K4: =IF($B4=0,"",$J4/$B4) | L4: 0.26365514 | M4: =IF($B4=0,"",(IF(K4>=L4,"Met","Unmet"))) | N4: =IF($B4=0,"",COUNTIFS('PART III-DEMOGRAPHICS'!$E$17:$E$2010,Data!$G$4,'PART III-DEMOGRAPHICS'!$Q$17:$Q$2010,$A4)) | O4: =IF($B4=0,"",$N4/$B4) | P4: 0.12448857 | Q4: =IF($B4=0,"",(IF(O4>=P4,"Met","Unmet"))) | R4: =IF($B4=0,"",COUNTIFS('PART III-DEMOGRAPHICS'!$E$17:$E$2010,Data!$G$5,'PART III-DEMOGRAPHICS'!$Q$17:$Q$2010,$A4)) | S4: =IF($B4=0,"",$R4/$B4) | T4: 0.010863039 | U4: =IF($B4=0,"",(IF(S4>=T4,"Met","Unmet"))) | V4: =IF($B4=0,"",COUNTIFS('PART III-DEMOGRAPHICS'!$F$17:$F$2010,"=Yes",'PART III-DEMOGRAPHICS'!$Q$17:$Q$2010,$A4)) | W4: =IF($B4=0,"",$V4/$B4) | X4: 0.14554409 | Y4: =IF($B4=0,"",(IF(W4>=X4,"Met","Unmet"))) | Z4: =IF($B4=0,"",COUNTIFS('PART III-DEMOGRAPHICS'!$E$17:$E$2010,Data!$G$6,'PART III-DEMOGRAPHICS'!$Q$17:$Q$2010,$A4)) | AA4: =IF($B4=0,"",$Z4/$B4) | AB4: 0.44010886 | AC4: =IF($B4=0,"",(IF(AA4>=AB4,"Met","Unmet"))) | AD4: =IF($B4=0,"",COUNTIFS('PART III-DEMOGRAPHICS'!$E$17:$E$2010,Data!$G$8,'PART III-DEMOGRAPHICS'!$Q$17:$Q$2010,$A4)) | AE4: =IF($B4=0,"",$AD4/$B4) | AF4: 0.012171143 | AG4: =IF($B4=0,"",(IF(AE4>=AF4,"Met","Unmet"))) | AH4: =IF($B4=0,"",COUNTIFS('PART III-DEMOGRAPHICS'!$E$17:$E$2010,Data!$G$7,'PART III-DEMOGRAPHICS'!$Q$17:$Q$2010,$A4)) | AI4: =IF($B4=0,"",$AH4/$B4) | AK4: =IF($B4=0,"",SUMIF('PART IV-V-SERVICES AND OUTCOMES'!$U$7:$U$2000,$A4,'PART IV-V-SERVICES AND OUTCOMES'!$T$7:$T$2000)) | AL4: =$AK4/$B4 -> #VALUE!
A5: Alpine | B5: =COUNTIF('PART III-DEMOGRAPHICS'!$Q$17:$Q$2010,A5) -> 0 | C5: {=IF(_xlfn.XLOOKUP('7-OB Report'!$C$2,Data!$C$51:$C$65,_xlfn.XLOOKUP($A5,Data!$F$50:$BM$50,Data!$F$51:$BM$65))=0,"",_xlfn.XLOOKUP('7-OB Report'!$C$2,Data!$C$51:$C$65,_xlfn.XLOOKUP($A5,Data!$F$50:$BM$50,Data!$F$51:$BM$65)))} | D5: =IF(C5="","",B5/C5) | F5: =IF($B5=0,"",COUNTIFS('PART III-DEMOGRAPHICS'!$E$17:$E$2010,Data!$G$2,'PART III-DEMOGRAPHICS'!$Q$17:$Q$2010,$A5)) | G5: =IF($B5=0,"",$F5/$B5) | H5: 0.1166348 | I5: =IF($B5=0,"",(IF(G5>=H5,"Met","Unmet"))) | J5: =IF($B5=0,"",COUNTIFS('PART III-DEMOGRAPHICS'!$E$17:$E$2010,Data!$G$3,'PART III-DEMOGRAPHICS'!$Q$17:$Q$2010,$A5)) | K5: =IF($B5=0,"",$J5/$B5) | L5: 0.0095602294 | M5: =IF($B5=0,"",(IF(K5>=L5,"Met","Unmet"))) | N5: =IF($B5=0,"",COUNTIFS('PART III-DEMOGRAPHICS'!$E$17:$E$2010,Data!$G$4,'PART III-DEMOGRAPHICS'!$Q$17:$Q$2010,$A5)) | O5: =IF($B5=0,"",$N5/$B5) | P5: 0 | Q5: =IF($B5=0,"",(IF(O5>=P5,"Met","Unmet"))) | R5: =IF($B5=0,"",COUNTIFS('PART III-DEMOGRAPHICS'!$E$17:$E$2010,Data!$G$5,'PART III-DEMOGRAPHICS'!$Q$17:$Q$2010,$A5)) | S5: =IF($B5=0,"",$R5/$B5) | T5: 0 | U5: =IF($B5=0,"",(IF(S5>=T5,"Met","Unmet"))) | V5: =IF($B5=0,"",COUNTIFS('PART III-DEMOGRAPHICS'!$F$17:$F$2010,"=Yes",'PART III-DEMOGRAPHICS'!$Q$17:$Q$2010,$A5)) | W5: =IF($B5=0,"",$V5/$B5) | X5: 0.038240918 | Y5: =IF($B5=0,"",(IF(W5>=X5,"Met","Unmet"))) | Z5: =IF($B5=0,"",COUNTIFS('PART III-DEMOGRAPHICS'!$E$17:$E$2010,Data!$G$6,'PART III-DEMOGRAPHICS'!$Q$17:$Q$2010,$A5)) | AA5: =IF($B5=0,"",$Z5/$B5) | AB5: 0.81070746 | AC5: =IF($B5=0,"",(IF(AA5>=AB5,"Met","Unmet"))) | AD5: =IF($B5=0,"",COUNTIFS('PART III-DEMOGRAPHICS'!$E$17:$E$2010,Data!$G$8,'PART III-DEMOGRAPHICS'!$Q$17:$Q$2010,$A5)) | AE5: =IF($B5=0,"",$AD5/$B5) | AF5: 0.024856597 | AG5: =IF($B5=0,"",(IF(AE5>=AF5,"Met","Unmet"))) | AH5: =IF($B5=0,"",COUNTIFS('PART III-DEMOGRAPHICS'!$E$17:$E$2010,Data!$G$7,'PART III-DEMOGRAPHICS'!$Q$17:$Q$2010,$A5)) | AI5: =IF($B5=0,"",$AH5/$B5) | AK5: =IF($B5=0,"",SUMIF('PART IV-V-SERVICES AND OUTCOMES'!$U$7:$U$2000,$A5,'PART IV-V-SERVICES AND OUTCOMES'!$T$7:$T$2000)) | AL5: =$AK5/$B5 -> #VALUE!
A6: Amador | B6: =COUNTIF('PART III-DEMOGRAPHICS'!$Q$17:$Q$2010,A6) -> 0 | C6: {=IF(_xlfn.XLOOKUP('7-OB Report'!$C$2,Data!$C$51:$C$65,_xlfn.XLOOKUP($A6,Data!$F$50:$BM$50,Data!$F$51:$BM$65))=0,"",_xlfn.XLOOKUP('7-OB Report'!$C$2,Data!$C$51:$C$65,_xlfn.XLOOKUP($A6,Data!$F$50:$BM$50,Data!$F$51:$BM$65)))} -> 3 | D6: =IF(C6="","",B6/C6) -> 0 | F6: =IF($B6=0,"",COUNTIFS('PART III-DEMOGRAPHICS'!$E$17:$E$2010,Data!$G$2,'PART III-DEMOGRAPHICS'!$Q$17:$Q$2010,$A6)) | G6: =IF($B6=0,"",$F6/$B6) | H6: 0.011215589 | I6: =IF($B6=0,"",(IF(G6>=H6,"Met","Unmet"))) | J6: =IF($B6=0,"",COUNTIFS('PART III-DEMOGRAPHICS'!$E$17:$E$2010,Data!$G$3,'PART III-DEMOGRAPHICS'!$Q$17:$Q$2010,$A6)) | K6: =IF($B6=0,"",$J6/$B6) | L6: 0.0096295457 | M6: =IF($B6=0,"",(IF(K6>=L6,"Met","Unmet"))) | N6: =IF($B6=0,"",COUNTIFS('PART III-DEMOGRAPHICS'!$E$17:$E$2010,Data!$G$4,'PART III-DEMOGRAPHICS'!$Q$17:$Q$2010,$A6)) | O6: =IF($B6=0,"",$N6/$B6) | P6: 0.018636003 | Q6: =IF($B6=0,"",(IF(O6>=P6,"Met","Unmet"))) | R6: =IF($B6=0,"",COUNTIFS('PART III-DEMOGRAPHICS'!$E$17:$E$2010,Data!$G$5,'PART III-DEMOGRAPHICS'!$Q$17:$Q$2010,$A6)) | S6: =IF($B6=0,"",$R6/$B6) | T6: 0.0015860428 | U6: =IF($B6=0,"",(IF(S6>=T6,"Met","Unmet"))) | V6: =IF($B6=0,"",COUNTIFS('PART III-DEMOGRAPHICS'!$F$17:$F$2010,"=Yes",'PART III-DEMOGRAPHICS'!$Q$17:$Q$2010,$A6)) | W6: =IF($B6=0,"",$V6/$B6) | X6: 0.080944828 | Y6: =IF($B6=0,"",(IF(W6>=X6,"Met","Unmet"))) | Z6: =IF($B6=0,"",COUNTIFS('PART III-DEMOGRAPHICS'!$E$17:$E$2010,Data!$G$6,'PART III-DEMOGRAPHICS'!$Q$17:$Q$2010,$A6)) | AA6: =IF($B6=0,"",$Z6/$B6) | AB6: 0.86309052 | AC6: =IF($B6=0,"",(IF(AA6>=AB6,"Met","Unmet"))) | AD6: =IF($B6=0,"",COUNTIFS('PART III-DEMOGRAPHICS'!$E$17:$E$2010,Data!$G$8,'PART III-DEMOGRAPHICS'!$Q$17:$Q$2010,$A6)) | AE6: =IF($B6=0,"",$AD6/$B6) | AF6: 0.014897474 | AG6: =IF($B6=0,"",(IF(AE6>=AF6,"Met","Unmet"))) | AH6: =IF($B6=0,"",COUNTIFS('PART III-DEMOGRAPHICS'!$E$17:$E$2010,Data!$G$7,'PART III-DEMOGRAPHICS'!$Q$17:$Q$2010,$A6)) | AI6: =IF($B6=0,"",$AH6/$B6) | AK6: =IF($B6=0,"",SUMIF('PART IV-V-SERVICES AND OUTCOMES'!$U$7:$U$2000,$A6,'PART IV-V-SERVICES AND OUTCOMES'!$T$7:$T$2000)) | AL6: =$AK6/$B6 -> #VALUE!
A7: Butte | B7: =COUNTIF('PART III-DEMOGRAPHICS'!$Q$17:$Q$2010,A7) -> 0 | C7: {=IF(_xlfn.XLOOKUP('7-OB Report'!$C$2,Data!$C$51:$C$65,_xlfn.XLOOKUP($A7,Data!$F$50:$BM$50,Data!$F$51:$BM$65))=0,"",_xlfn.XLOOKUP('7-OB Report'!$C$2,Data!$C$51:$C$65,_xlfn.XLOOKUP($A7,Data!$F$50:$BM$50,Data!$F$51:$BM$65)))} -> 16 | D7: =IF(C7="","",B7/C7) -> 0 | F7: =IF($B7=0,"",COUNTIFS('PART III-DEMOGRAPHICS'!$E$17:$E$2010,Data!$G$2,'PART III-DEMOGRAPHICS'!$Q$17:$Q$2010,$A7)) | G7: =IF($B7=0,"",$F7/$B7) | H7: 0.013065768 | I7: =IF($B7=0,"",(IF(G7>=H7,"Met","Unmet"))) | J7: =IF($B7=0,"",COUNTIFS('PART III-DEMOGRAPHICS'!$E$17:$E$2010,Data!$G$3,'PART III-DEMOGRAPHICS'!$Q$17:$Q$2010,$A7)) | K7: =IF($B7=0,"",$J7/$B7) | L7: 0.024315219 | M7: =IF($B7=0,"",(IF(K7>=L7,"Met","Unmet"))) | N7: =IF($B7=0,"",COUNTIFS('PART III-DEMOGRAPHICS'!$E$17:$E$2010,Data!$G$4,'PART III-DEMOGRAPHICS'!$Q$17:$Q$2010,$A7)) | O7: =IF($B7=0,"",$N7/$B7) | P7: 0.012084371 | Q7: =IF($B7=0,"",(IF(O7>=P7,"Met","Unmet"))) | R7: =IF($B7=0,"",COUNTIFS('PART III-DEMOGRAPHICS'!$E$17:$E$2010,Data!$G$5,'PART III-DEMOGRAPHICS'!$Q$17:$Q$2010,$A7)) | S7: =IF($B7=0,"",$R7/$B7) | T7: 0.0015526586 | U7: =IF($B7=0,"",(IF(S7>=T7,"Met","Unmet"))) | V7: =IF($B7=0,"",COUNTIFS('PART III-DEMOGRAPHICS'!$F$17:$F$2010,"=Yes",'PART III-DEMOGRAPHICS'!$Q$17:$Q$2010,$A7)) | W7: =IF($B7=0,"",$V7/$B7) | X7: 0.09028856 | Y7: =IF($B7=0,"",(IF(W7>=X7,"Met","Unmet"))) | Z7: =IF($B7=0,"",COUNTIFS('PART III-DEMOGRAPHICS'!$E$17:$E$2010,Data!$G$6,'PART III-DEMOGRAPHICS'!$Q$17:$Q$2010,$A7)) | AA7: =IF($B7=0,"",$Z7/$B7) | AB7: 0.84486597 | AC7: =IF($B7=0,"",(IF(AA7>=AB7,"Met","Unmet"))) | AD7: =IF($B7=0,"",COUNTIFS('PART III-DEMOGRAPHICS'!$E$17:$E$2010,Data!$G$8,'PART III-DEMOGRAPHICS'!$Q$17:$Q$2010,$A7)) | AE7: =IF($B7=0,"",$AD7/$B7) | AF7: 0.01382745 | AG7: =IF($B7=0,"",(IF(AE7>=AF7,"Met","Unmet"))) | AH7: =IF($B7=0,"",COUNTIFS('PART III-DEMOGRAPHICS'!$E$17:$E$2010,Data!$G$7,'PART III-DEMOGRAPHICS'!$Q$17:$Q$2010,$A7)) | AI7: =IF($B7=0,"",$AH7/$B7) | AK7: =IF($B7=0,"",SUMIF('PART IV-V-SERVICES AND OUTCOMES'!$U$7:$U$2000,$A7,'PART IV-V-SERVICES AND OUTCOMES'!$T$7:$T$2000)) | AL7: =$AK7/$B7 -> #VALUE!
A8: Calaveras | B8: =COUNTIF('PART III-DEMOGRAPHICS'!$Q$17:$Q$2010,A8) -> 0 | C8: {=IF(_xlfn.XLOOKUP('7-OB Report'!$C$2,Data!$C$51:$C$65,_xlfn.XLOOKUP($A8,Data!$F$50:$BM$50,Data!$F$51:$BM$65))=0,"",_xlfn.XLOOKUP('7-OB Report'!$C$2,Data!$C$51:$C$65,_xlfn.XLOOKUP($A8,Data!$F$50:$BM$50,Data!$F$51:$BM$65)))} -> 5 | D8: =IF(C8="","",B8/C8) -> 0 | F8: =IF($B8=0,"",COUNTIFS('PART III-DEMOGRAPHICS'!$E$17:$E$2010,Data!$G$2,'PART III-DEMOGRAPHICS'!$Q$17:$Q$2010,$A8)) | G8: =IF($B8=0,"",$F8/$B8) | H8: 0.010425096 | I8: =IF($B8=0,"",(IF(G8>=H8,"Met","Unmet"))) | J8: =IF($B8=0,"",COUNTIFS('PART III-DEMOGRAPHICS'!$E$17:$E$2010,Data!$G$3,'PART III-DEMOGRAPHICS'!$Q$17:$Q$2010,$A8)) | K8: =IF($B8=0,"",$J8/$B8) | L8: 0.010377493 | M8: =IF($B8=0,"",(IF(K8>=L8,"Met","Unmet"))) | N8: =IF($B8=0,"",COUNTIFS('PART III-DEMOGRAPHICS'!$E$17:$E$2010,Data!$G$4,'PART III-DEMOGRAPHICS'!$Q$17:$Q$2010,$A8)) | O8: =IF($B8=0,"",$N8/$B8) | P8: 0.0048555243 | Q8: =IF($B8=0,"",(IF(O8>=P8,"Met","Unmet"))) | R8: =IF($B8=0,"",COUNTIFS('PART III-DEMOGRAPHICS'!$E$17:$E$2010,Data!$G$5,'PART III-DEMOGRAPHICS'!$Q$17:$Q$2010,$A8)) | S8: =IF($B8=0,"",$R8/$B8) | T8: 0.0014280954 | U8: =IF($B8=0,"",(IF(S8>=T8,"Met","Unmet"))) | V8: =IF($B8=0,"",COUNTIFS('PART III-DEMOGRAPHICS'!$F$17:$F$2010,"=Yes",'PART III-DEMOGRAPHICS'!$Q$17:$Q$2010,$A8)) | W8: =IF($B8=0,"",$V8/$B8) | X8: 0.07230923 | Y8: =IF($B8=0,"",(IF(W8>=X8,"Met","Unmet"))) | Z8: =IF($B8=0,"",COUNTIFS('PART III-DEMOGRAPHICS'!$E$17:$E$2010,Data!$G$6,'PART III-DEMOGRAPHICS'!$Q$17:$Q$2010,$A8)) | AA8: =IF($B8=0,"",$Z8/$B8) | AB8: 0.88565716 | AC8: =IF($B8=0,"",(IF(AA8>=AB8,"Met","Unmet"))) | AD8: =IF($B8=0,"",COUNTIFS('PART III-DEMOGRAPHICS'!$E$17:$E$2010,Data!$G$8,'PART III-DEMOGRAPHICS'!$Q$17:$Q$2010,$A8)) | AE8: =IF($B8=0,"",$AD8/$B8) | AF8: 0.014947398 | AG8: =IF($B8=0,"",(IF(AE8>=AF8,"Met","Unmet"))) | AH8: =IF($B8=0,"",COUNTIFS('PART III-DEMOGRAPHICS'!$E$17:$E$2010,Data!$G$7,'PART III-DEMOGRAPHICS'!$Q$17:$Q$2010,$A8)) | AI8: =IF($B8=0,"",$AH8/$B8) | AK8: =IF($B8=0,"",SUMIF('PART IV-V-SERVICES AND OUTCOMES'!$U$7:$U$2000,$A8,'PART IV-V-SERVICES AND OUTCOMES'!$T$7:$T$2000)) | AL8: =$AK8/$B8 -> #VALUE!
A9: Colusa | B9: =COUNTIF('PART III-DEMOGRAPHICS'!$Q$17:$Q$2010,A9) -> 0 | C9: {=IF(_xlfn.XLOOKUP('7-OB Report'!$C$2,Data!$C$51:$C$65,_xlfn.XLOOKUP($A9,Data!$F$50:$BM$50,Data!$F$51:$BM$65))=0,"",_xlfn.XLOOKUP('7-OB Report'!$C$2,Data!$C$51:$C$65,_xlfn.XLOOKUP($A9,Data!$F$50:$BM$50,Data!$F$51:$BM$65)))} | D9: =IF(C9="","",B9/C9) | F9: =IF($B9=0,"",COUNTIFS('PART III-DEMOGRAPHICS'!$E$17:$E$2010,Data!$G$2,'PART III-DEMOGRAPHICS'!$Q$17:$Q$2010,$A9)) | G9: =IF($B9=0,"",$F9/$B9) | H9: 0.017081962 | I9: =IF($B9=0,"",(IF(G9>=H9,"Met","Unmet"))) | J9: =IF($B9=0,"",COUNTIFS('PART III-DEMOGRAPHICS'!$E$17:$E$2010,Data!$G$3,'PART III-DEMOGRAPHICS'!$Q$17:$Q$2010,$A9)) | K9: =IF($B9=0,"",$J9/$B9) | L9: 0.016455101 | M9: =IF($B9=0,"",(IF(K9>=L9,"Met","Unmet"))) | N9: =IF($B9=0,"",COUNTIFS('PART III-DEMOGRAPHICS'!$E$17:$E$2010,Data!$G$4,'PART III-DEMOGRAPHICS'!$Q$17:$Q$2010,$A9)) | O9: =IF($B9=0,"",$N9/$B9) | P9: 0.0097163454 | Q9: =IF($B9=0,"",(IF(O9>=P9,"Met","Unmet"))) | R9: =IF($B9=0,"",COUNTIFS('PART III-DEMOGRAPHICS'!$E$17:$E$2010,Data!$G$5,'PART III-DEMOGRAPHICS'!$Q$17:$Q$2010,$A9)) | S9: =IF($B9=0,"",$R9/$B9) | T9: 0.0039178812 | U9: =IF($B9=0,"",(IF(S9>=T9,"Met","Unmet"))) | V9: =IF($B9=0,"",COUNTIFS('PART III-DEMOGRAPHICS'!$F$17:$F$2010,"=Yes",'PART III-DEMOGRAPHICS'!$Q$17:$Q$2010,$A9)) | W9: =IF($B9=0,"",$V9/$B9) | X9: 0.34978843 | Y9: =IF($B9=0,"",(IF(W9>=X9,"Met","Unmet"))) | Z9: =IF($B9=0,"",COUNTIFS('PART III-DEMOGRAPHICS'!$E$17:$E$2010,Data!$G$6,'PART III-DEMOGRAPHICS'!$Q$17:$Q$2010,$A9)) | AA9: =IF($B9=0,"",$Z9/$B9) | AB9: 0.59207021 | AC9: =IF($B9=0,"",(IF(AA9>=AB9,"Met","Unmet"))) | AD9: =IF($B9=0,"",COUNTIFS('PART III-DEMOGRAPHICS'!$E$17:$E$2010,Data!$G$8,'PART III-DEMOGRAPHICS'!$Q$17:$Q$2010,$A9)) | AE9: =IF($B9=0,"",$AD9/$B9) | AF9: 0.010970067 | AG9: =IF($B9=0,"",(IF(AE9>=AF9,"Met","Unmet"))) | AH9: =IF($B9=0,"",COUNTIFS('PART III-DEMOGRAPHICS'!$E$17:$E$2010,Data!$G$7,'PART III-DEMOGRAPHICS'!$Q$17:$Q$2010,$A9)) | AI9: =IF($B9=0,"",$AH9/$B9) | AK9: =IF($B9=0,"",SUMIF('PART IV-V-SERVICES AND OUTCOMES'!$U$7:$U$2000,$A9,'PART IV-V-SERVICES AND OUTCOMES'!$T$7:$T$2000)) | AL9: =$AK9/$B9 -> #VALUE!
A10: Contra Costa | B10: =COUNTIF('PART III-DEMOGRAPHICS'!$Q$17:$Q$2010,A10) -> 0 | C10: {=IF(_xlfn.XLOOKUP('7-OB Report'!$C$2,Data!$C$51:$C$65,_xlfn.XLOOKUP($A10,Data!$F$50:$BM$50,Data!$F$51:$BM$65))=0,"",_xlfn.XLOOKUP('7-OB Report'!$C$2,Data!$C$51:$C$65,_xlfn.XLOOKUP($A10,Data!$F$50:$BM$50,Data!$F$51:$BM$65)))} | D10: =IF(C10="","",B10/C10) | F10: =IF($B10=0,"",COUNTIFS('PART III-DEMOGRAPHICS'!$E$17:$E$2010,Data!$G$2,'PART III-DEMOGRAPHICS'!$Q$17:$Q$2010,$A10)) | G10: =IF($B10=0,"",$F10/$B10) | H10: 0.0033051 | I10: =IF($B10=0,"",(IF(G10>=H10,"Met","Unmet"))) | J10: =IF($B10=0,"",COUNTIFS('PART III-DEMOGRAPHICS'!$E$17:$E$2010,Data!$G$3,'PART III-DEMOGRAPHICS'!$Q$17:$Q$2010,$A10)) | K10: =IF($B10=0,"",$J10/$B10) | L10: 0.15542969 | M10: =IF($B10=0,"",(IF(K10>=L10,"Met","Unmet"))) | N10: =IF($B10=0,"",COUNTIFS('PART III-DEMOGRAPHICS'!$E$17:$E$2010,Data!$G$4,'PART III-DEMOGRAPHICS'!$Q$17:$Q$2010,$A10)) | O10: =IF($B10=0,"",$N10/$B10) | P10: 0.08114675 | Q10: =IF($B10=0,"",(IF(O10>=P10,"Met","Unmet"))) | R10: =IF($B10=0,"",COUNTIFS('PART III-DEMOGRAPHICS'!$E$17:$E$2010,Data!$G$5,'PART III-DEMOGRAPHICS'!$Q$17:$Q$2010,$A10)) | S10: =IF($B10=0,"",$R10/$B10) | T10: 0.0039241245 | U10: =IF($B10=0,"",(IF(S10>=T10,"Met","Unmet"))) | V10: =IF($B10=0,"",COUNTIFS('PART III-DEMOGRAPHICS'!$F$17:$F$2010,"=Yes",'PART III-DEMOGRAPHICS'!$Q$17:$Q$2010,$A10)) | W10: =IF($B10=0,"",$V10/$B10) | X10: 0.14350733 | Y10: =IF($B10=0,"",(IF(W10>=X10,"Met","Unmet"))) | Z10: =IF($B10=0,"",COUNTIFS('PART III-DEMOGRAPHICS'!$E$17:$E$2010,Data!$G$6,'PART III-DEMOGRAPHICS'!$Q$17:$Q$2010,$A10)) | AA10: =IF($B10=0,"",$Z10/$B10) | AB10: 0.6009119 | AC10: =IF($B10=0,"",(IF(AA10>=AB10,"Met","Unmet"))) | AD10: =IF($B10=0,"",COUNTIFS('PART III-DEMOGRAPHICS'!$E$17:$E$2010,Data!$G$8,'PART III-DEMOGRAPHICS'!$Q$17:$Q$2010,$A10)) | AE10: =IF($B10=0,"",$AD10/$B10) | AF10: 0.0117751 | AG10: =IF($B10=0,"",(IF(AE10>=AF10,"Met","Unmet"))) | AH10: =IF($B10=0,"",COUNTIFS('PART III-DEMOGRAPHICS'!$E$17:$E$2010,Data!$G$7,'PART III-DEMOGRAPHICS'!$Q$17:$Q$2010,$A10)) | AI10: =IF($B10=0,"",$AH10/$B10) | AK10: =IF($B10=0,"",SUMIF('PART IV-V-SERVICES AND OUTCOMES'!$U$7:$U$2000,$A10,'PART IV-V-SERVICES AND OUTCOMES'!$T$7:$T$2000)) | AL10: =$AK10/$B10 -> #VALUE!
A11: Del Norte | B11: =COUNTIF('PART III-DEMOGRAPHICS'!$Q$17:$Q$2010,A11) -> 0 | C11: {=IF(_xlfn.XLOOKUP('7-OB Report'!$C$2,Data!$C$51:$C$65,_xlfn.XLOOKUP($A11,Data!$F$50:$BM$50,Data!$F$51:$BM$65))=0,"",_xlfn.XLOOKUP('7-OB Report'!$C$2,Data!$C$51:$C$65,_xlfn.XLOOKUP($A11,Data!$F$50:$BM$50,Data!$F$51:$BM$65)))} | D11: =IF(C11="","",B11/C11) | F11: =IF($B11=0,"",COUNTIFS('PART III-DEMOGRAPHICS'!$E$17:$E$2010,Data!$G$2,'PART III-DEMOGRAPHICS'!$Q$17:$Q$2010,$A11)) | G11: =IF($B11=0,"",$F11/$B11) | H11: 0.048165386 | I11: =IF($B11=0,"",(IF(G11>=H11,"Met","Unmet"))) | J11: =IF($B11=0,"",COUNTIFS('PART III-DEMOGRAPHICS'!$E$17:$E$2010,Data!$G$3,'PART III-DEMOGRAPHICS'!$Q$17:$Q$2010,$A11)) | K11: =IF($B11=0,"",$J11/$B11) | L11: 0.023703864 | M11: =IF($B11=0,"",(IF(K11>=L11,"Met","Unmet"))) | N11: =IF($B11=0,"",COUNTIFS('PART III-DEMOGRAPHICS'!$E$17:$E$2010,Data!$G$4,'PART III-DEMOGRAPHICS'!$Q$17:$Q$2010,$A11)) | O11: =IF($B11=0,"",$N11/$B11) | P11: 0.023812101 | Q11: =IF($B11=0,"",(IF(O11>=P11,"Met","Unmet"))) | R11: =IF($B11=0,"",COUNTIFS('PART III-DEMOGRAPHICS'!$E$17:$E$2010,Data!$G$5,'PART III-DEMOGRAPHICS'!$Q$17:$Q$2010,$A11)) | S11: =IF($B11=0,"",$R11/$B11) | T11: 0.0015153155 | U11: =IF($B11=0,"",(IF(S11>=T11,"Met","Unmet"))) | V11: =IF($B11=0,"",COUNTIFS('PART III-DEMOGRAPHICS'!$F$17:$F$2010,"=Yes",'PART III-DEMOGRAPHICS'!$Q$17:$Q$2010,$A11)) | W11: =IF($B11=0,"",$V11/$B11) | X11: 0.093300141 | Y11: =IF($B11=0,"",(IF(W11>=X11,"Met","Unmet"))) | Z11: =IF($B11=0,"",COUNTIFS('PART III-DEMOGRAPHICS'!$E$17:$E$2010,Data!$G$6,'PART III-DEMOGRAPHICS'!$Q$17:$Q$2010,$A11)) | AA11: =IF($B11=0,"",$Z11/$B11) | AB11: 0.78958762 | AC11: =IF($B11=0,"",(IF(AA11>=AB11,"Met","Unmet"))) | AD11: =IF($B11=0,"",COUNTIFS('PART III-DEMOGRAPHICS'!$E$17:$E$2010,Data!$G$8,'PART III-DEMOGRAPHICS'!$Q$17:$Q$2010,$A11)) | AE11: =IF($B11=0,"",$AD11/$B11) | AF11: 0.019915575 | AG11: =IF($B11=0,"",(IF(AE11>=AF11,"Met","Unmet"))) | AH11: =IF($B11=0,"",COUNTIFS('PART III-DEMOGRAPHICS'!$E$17:$E$2010,Data!$G$7,'PART III-DEMOGRAPHICS'!$Q$17:$Q$2010,$A11)) | AI11: =IF($B11=0,"",$AH11/$B11) | AK11: =IF($B11=0,"",SUMIF('PART IV-V-SERVICES AND OUTCOMES'!$U$7:$U$2000,$A11,'PART IV-V-SERVICES AND OUTCOMES'!$T$7:$T$2000)) | AL11: =$AK11/$B11 -> #VALUE!
A12: El Dorado | B12: =COUNTIF('PART III-DEMOGRAPHICS'!$Q$17:$Q$2010,A12) -> 0 | C12: {=IF(_xlfn.XLOOKUP('7-OB Report'!$C$2,Data!$C$51:$C$65,_xlfn.XLOOKUP($A12,Data!$F$50:$BM$50,Data!$F$51:$BM$65))=0,"",_xlfn.XLOOKUP('7-OB Report'!$C$2,Data!$C$51:$C$65,_xlfn.XLOOKUP($A12,Data!$F$50:$BM$50,Data!$F$51:$BM$65)))} -> 24 | D12: =IF(C12="","",B12/C12) -> 0 | F12: =IF($B12=0,"",COUNTIFS('PART III-DEMOGRAPHICS'!$E$17:$E$2010,Data!$G$2,'PART III-DEMOGRAPHICS'!$Q$17:$Q$2010,$A12)) | G12: =IF($B12=0,"",$F12/$B12) | H12: 0.0078804384 | I12: =IF($B12=0,"",(IF(G12>=H12,"Met","Unmet"))) | J12: =IF($B12=0,"",COUNTIFS('PART III-DEMOGRAPHICS'!$E$17:$E$2010,Data!$G$3,'PART III-DEMOGRAPHICS'!$Q$17:$Q$2010,$A12)) | K12: =IF($B12=0,"",$J12/$B12) | L12: 0.036626278 | M12: =IF($B12=0,"",(IF(K12>=L12,"Met","Unmet"))) | N12: =IF($B12=0,"",COUNTIFS('PART III-DEMOGRAPHICS'!$E$17:$E$2010,Data!$G$4,'PART III-DEMOGRAPHICS'!$Q$17:$Q$2010,$A12)) | O12: =IF($B12=0,"",$N12/$B12) | P12: 0.0063806554 | Q12: =IF($B12=0,"",(IF(O12>=P12,"Met","Unmet"))) | R12: =IF($B12=0,"",COUNTIFS('PART III-DEMOGRAPHICS'!$E$17:$E$2010,Data!$G$5,'PART III-DEMOGRAPHICS'!$Q$17:$Q$2010,$A12)) | S12: =IF($B12=0,"",$R12/$B12) | T12: 0.0012235071 | U12: =IF($B12=0,"",(IF(S12>=T12,"Met","Unmet"))) | V12: =IF($B12=0,"",COUNTIFS('PART III-DEMOGRAPHICS'!$F$17:$F$2010,"=Yes",'PART III-DEMOGRAPHICS'!$Q$17:$Q$2010,$A12)) | W12: =IF($B12=0,"",$V12/$B12) | X12: 0.070160898 | Y12: =IF($B12=0,"",(IF(W12>=X12,"Met","Unmet"))) | Z12: =IF($B12=0,"",COUNTIFS('PART III-DEMOGRAPHICS'!$E$17:$E$2010,Data!$G$6,'PART III-DEMOGRAPHICS'!$Q$17:$Q$2010,$A12)) | AA12: =IF($B12=0,"",$Z12/$B12) | AB12: 0.86012551 | AC12: =IF($B12=0,"",(IF(AA12>=AB12,"Met","Unmet"))) | AD12: =IF($B12=0,"",COUNTIFS('PART III-DEMOGRAPHICS'!$E$17:$E$2010,Data!$G$8,'PART III-DEMOGRAPHICS'!$Q$17:$Q$2010,$A12)) | AE12: =IF($B12=0,"",$AD12/$B12) | AF12: 0.017602715 | AG12: =IF($B12=0,"",(IF(AE12>=AF12,"Met","Unmet"))) | AH12: =IF($B12=0,"",COUNTIFS('PART III-DEMOGRAPHICS'!$E$17:$E$2010,Data!$G$7,'PART III-DEMOGRAPHICS'!$Q$17:$Q$2010,$A12)) | AI12: =IF($B12=0,"",$AH12/$B12) | AK12: =IF($B12=0,"",SUMIF('PART IV-V-SERVICES AND OUTCOMES'!$U$7:$U$2000,$A12,'PART IV-V-SERVICES AND OUTCOMES'!$T$7:$T$2000)) | AL12: =$AK12/$B12 -> #VALUE!
A13: Fresno | B13: =COUNTIF('PART III-DEMOGRAPHICS'!$Q$17:$Q$2010,A13) -> 0 | C13: {=IF(_xlfn.XLOOKUP('7-OB Report'!$C$2,Data!$C$51:$C$65,_xlfn.XLOOKUP($A13,Data!$F$50:$BM$50,Data!$F$51:$BM$65))=0,"",_xlfn.XLOOKUP('7-OB Report'!$C$2,Data!$C$51:$C$65,_xlfn.XLOOKUP($A13,Data!$F$50:$BM$50,Data!$F$51:$BM$65)))} | D13: =IF(C13="","",B13/C13) | F13: =IF($B13=0,"",COUNTIFS('PART III-DEMOGRAPHICS'!$E$17:$E$2010,Data!$G$2,'PART III-DEMOGRAPHICS'!$Q$17:$Q$2010,$A13)) | G13: =IF($B13=0,"",$F13/$B13) | H13: 0.0079103387 | I13: =IF($B13=0,"",(IF(G13>=H13,"Met","Unmet"))) | J13: =IF($B13=0,"",COUNTIFS('PART III-DEMOGRAPHICS'!$E$17:$E$2010,Data!$G$3,'PART III-DEMOGRAPHICS'!$Q$17:$Q$2010,$A13)) | K13: =IF($B13=0,"",$J13/$B13) | L13: 0.087300274 | M13: =IF($B13=0,"",(IF(K13>=L13,"Met","Unmet"))) | N13: =IF($B13=0,"",COUNTIFS('PART III-DEMOGRAPHICS'!$E$17:$E$2010,Data!$G$4,'PART III-DEMOGRAPHICS'!$Q$17:$Q$2010,$A13)) | O13: =IF($B13=0,"",$N13/$B13) | P13: 0.045419874 | Q13: =IF($B13=0,"",(IF(O13>=P13,"Met","Unmet"))) | R13: =IF($B13=0,"",COUNTIFS('PART III-DEMOGRAPHICS'!$E$17:$E$2010,Data!$G$5,'PART III-DEMOGRAPHICS'!$Q$17:$Q$2010,$A13)) | S13: =IF($B13=0,"",$R13/$B13) | T13: 0.0010009 | U13: =IF($B13=0,"",(IF(S13>=T13,"Met","Unmet"))) | V13: =IF($B13=0,"",COUNTIFS('PART III-DEMOGRAPHICS'!$F$17:$F$2010,"=Yes",'PART III-DEMOGRAPHICS'!$Q$17:$Q$2010,$A13)) | W13: =IF($B13=0,"",$V13/$B13) | X13: 0.37171731 | Y13: =IF($B13=0,"",(IF(W13>=X13,"Met","Unmet"))) | Z13: =IF($B13=0,"",COUNTIFS('PART III-DEMOGRAPHICS'!$E$17:$E$2010,Data!$G$6,'PART III-DEMOGRAPHICS'!$Q$17:$Q$2010,$A13)) | AA13: =IF($B13=0,"",$Z13/$B13) | AB13: 0.47689253 | AC13: =IF($B13=0,"",(IF(AA13>=AB13,"Met","Unmet"))) | AD13: =IF($B13=0,"",COUNTIFS('PART III-DEMOGRAPHICS'!$E$17:$E$2010,Data!$G$8,'PART III-DEMOGRAPHICS'!$Q$17:$Q$2010,$A13)) | AE13: =IF($B13=0,"",$AD13/$B13) | AF13: 0.009758775 | AG13: =IF($B13=0,"",(IF(AE13>=AF13,"Met","Unmet"))) | AH13: =IF($B13=0,"",COUNTIFS('PART III-DEMOGRAPHICS'!$E$17:$E$2010,Data!$G$7,'PART III-DEMOGRAPHICS'!$Q$17:$Q$2010,$A13)) | AI13: =IF($B13=0,"",$AH13/$B13) | AK13: =IF($B13=0,"",SUMIF('PART IV-V-SERVICES AND OUTCOMES'!$U$7:$U$2000,$A13,'PART IV-V-SERVICES AND OUTCOMES'!$T$7:$T$2000)) | AL13: =$AK13/$B13 -> #VALUE!
A14: Glenn | B14: =COUNTIF('PART III-DEMOGRAPHICS'!$Q$17:$Q$2010,A14) -> 0 | C14: {=IF(_xlfn.XLOOKUP('7-OB Report'!$C$2,Data!$C$51:$C$65,_xlfn.XLOOKUP($A14,Data!$F$50:$BM$50,Data!$F$51:$BM$65))=0,"",_xlfn.XLOOKUP('7-OB Report'!$C$2,Data!$C$51:$C$65,_xlfn.XLOOKUP($A14,Data!$F$50:$BM$50,Data!$F$51:$BM$65)))} -> 4 | D14: =IF(C14="","",B14/C14) -> 0 | F14: =IF($B14=0,"",COUNTIFS('PART III-DEMOGRAPHICS'!$E$17:$E$2010,Data!$G$2,'PART III-DEMOGRAPHICS'!$Q$17:$Q$2010,$A14)) | G14: =IF($B14=0,"",$F14/$B14) | H14: 0.017464278 | I14: =IF($B14=0,"",(IF(G14>=H14,"Met","Unmet"))) | J14: =IF($B14=0,"",COUNTIFS('PART III-DEMOGRAPHICS'!$E$17:$E$2010,Data!$G$3,'PART III-DEMOGRAPHICS'!$Q$17:$Q$2010,$A14)) | K14: =IF($B14=0,"",$J14/$B14) | L14: 0.021093218 | M14: =IF($B14=0,"",(IF(K14>=L14,"Met","Unmet"))) | N14: =IF($B14=0,"",COUNTIFS('PART III-DEMOGRAPHICS'!$E$17:$E$2010,Data!$G$4,'PART III-DEMOGRAPHICS'!$Q$17:$Q$2010,$A14)) | O14: =IF($B14=0,"",$N14/$B14) | P14: 0.0081651168 | Q14: =IF($B14=0,"",(IF(O14>=P14,"Met","Unmet"))) | R14: =IF($B14=0,"",COUNTIFS('PART III-DEMOGRAPHICS'!$E$17:$E$2010,Data!$G$5,'PART III-DEMOGRAPHICS'!$Q$17:$Q$2010,$A14)) | S14: =IF($B14=0,"",$R14/$B14) | T14: 0.001134044 | U14: =IF($B14=0,"",(IF(S14>=T14,"Met","Unmet"))) | V14: =IF($B14=0,"",COUNTIFS('PART III-DEMOGRAPHICS'!$F$17:$F$2010,"=Yes",'PART III-DEMOGRAPHICS'!$Q$17:$Q$2010,$A14)) | W14: =IF($B14=0,"",$V14/$B14) | X14: 0.22374688 | Y14: =IF($B14=0,"",(IF(W14>=X14,"Met","Unmet"))) | Z14: =IF($B14=0,"",COUNTIFS('PART III-DEMOGRAPHICS'!$E$17:$E$2010,Data!$G$6,'PART III-DEMOGRAPHICS'!$Q$17:$Q$2010,$A14)) | AA14: =IF($B14=0,"",$Z14/$B14) | AB14: 0.71784985 | AC14: =IF($B14=0,"",(IF(AA14>=AB14,"Met","Unmet"))) | AD14: =IF($B14=0,"",COUNTIFS('PART III-DEMOGRAPHICS'!$E$17:$E$2010,Data!$G$8,'PART III-DEMOGRAPHICS'!$Q$17:$Q$2010,$A14)) | AE14: =IF($B14=0,"",$AD14/$B14) | AF14: 0.010546609 | AG14: =IF($B14=0,"",(IF(AE14>=AF14,"Met","Unmet"))) | AH14: =IF($B14=0,"",COUNTIFS('PART III-DEMOGRAPHICS'!$E$17:$E$2010,Data!$G$7,'PART III-DEMOGRAPHICS'!$Q$17:$Q$2010,$A14)) | AI14: =IF($B14=0,"",$AH14/$B14) | AK14: =IF($B14=0,"",SUMIF('PART IV-V-SERVICES AND OUTCOMES'!$U$7:$U$2000,$A14,'PART IV-V-SERVICES AND OUTCOMES'!$T$7:$T$2000)) | AL14: =$AK14/$B14 -> #VALUE!
